<?xml version="1.0" encoding="utf-8"?><testsuites><testsuite name="pytest" errors="3" failures="0" skipped="0" tests="3" time="0.348" timestamp="2022-11-12T11:11:31.547964" hostname="moonstar"><testcase classname="" name="tests.test_add" time="0.000"><error message="collection failure">ImportError while importing test module '/home/fabio/Documents/cursos/linuxtips/python_base/pb-dundie-rewards/tests/test_add.py'.
Hint: make sure your test modules/packages have valid Python names.
Traceback:
.venv/lib/python3.10/site-packages/_pytest/python.py:608: in _importtestmodule
    mod = import_path(self.path, mode=importmode, root=self.config.rootpath)
.venv/lib/python3.10/site-packages/_pytest/pathlib.py:533: in import_path
    importlib.import_module(module_name)
/usr/lib/python3.10/importlib/__init__.py:126: in import_module
    return _bootstrap._gcd_import(name[level:], package, level)
&lt;frozen importlib._bootstrap&gt;:1050: in _gcd_import
    ???
&lt;frozen importlib._bootstrap&gt;:1027: in _find_and_load
    ???
&lt;frozen importlib._bootstrap&gt;:1006: in _find_and_load_unlocked
    ???
&lt;frozen importlib._bootstrap&gt;:688: in _load_unlocked
    ???
.venv/lib/python3.10/site-packages/_pytest/assertion/rewrite.py:168: in exec_module
    exec(co, module.__dict__)
tests/test_add.py:4: in &lt;module&gt;
    from dundie.database import add_person, commit, connect
E   ImportError: cannot import name 'add_person' from 'dundie.database' (/home/fabio/Documents/cursos/linuxtips/python_base/pb-dundie-rewards/dundie/database.py)</error></testcase><testcase classname="" name="tests.test_database" time="0.000"><error message="collection failure">ImportError while importing test module '/home/fabio/Documents/cursos/linuxtips/python_base/pb-dundie-rewards/tests/test_database.py'.
Hint: make sure your test modules/packages have valid Python names.
Traceback:
.venv/lib/python3.10/site-packages/_pytest/python.py:608: in _importtestmodule
    mod = import_path(self.path, mode=importmode, root=self.config.rootpath)
.venv/lib/python3.10/site-packages/_pytest/pathlib.py:533: in import_path
    importlib.import_module(module_name)
/usr/lib/python3.10/importlib/__init__.py:126: in import_module
    return _bootstrap._gcd_import(name[level:], package, level)
&lt;frozen importlib._bootstrap&gt;:1050: in _gcd_import
    ???
&lt;frozen importlib._bootstrap&gt;:1027: in _find_and_load
    ???
&lt;frozen importlib._bootstrap&gt;:1006: in _find_and_load_unlocked
    ???
&lt;frozen importlib._bootstrap&gt;:688: in _load_unlocked
    ???
.venv/lib/python3.10/site-packages/_pytest/assertion/rewrite.py:168: in exec_module
    exec(co, module.__dict__)
tests/test_database.py:3: in &lt;module&gt;
    from dundie.database import EMPTY_DB, add_movement, add_person, commit, connect
E   ImportError: cannot import name 'EMPTY_DB' from 'dundie.database' (/home/fabio/Documents/cursos/linuxtips/python_base/pb-dundie-rewards/dundie/database.py)</error></testcase><testcase classname="" name="tests.test_read" time="0.000"><error message="collection failure">ImportError while importing test module '/home/fabio/Documents/cursos/linuxtips/python_base/pb-dundie-rewards/tests/test_read.py'.
Hint: make sure your test modules/packages have valid Python names.
Traceback:
.venv/lib/python3.10/site-packages/_pytest/python.py:608: in _importtestmodule
    mod = import_path(self.path, mode=importmode, root=self.config.rootpath)
.venv/lib/python3.10/site-packages/_pytest/pathlib.py:533: in import_path
    importlib.import_module(module_name)
/usr/lib/python3.10/importlib/__init__.py:126: in import_module
    return _bootstrap._gcd_import(name[level:], package, level)
&lt;frozen importlib._bootstrap&gt;:1050: in _gcd_import
    ???
&lt;frozen importlib._bootstrap&gt;:1027: in _find_and_load
    ???
&lt;frozen importlib._bootstrap&gt;:1006: in _find_and_load_unlocked
    ???
&lt;frozen importlib._bootstrap&gt;:688: in _load_unlocked
    ???
.venv/lib/python3.10/site-packages/_pytest/assertion/rewrite.py:168: in exec_module
    exec(co, module.__dict__)
tests/test_read.py:4: in &lt;module&gt;
    from dundie.database import add_person, commit, connect
E   ImportError: cannot import name 'add_person' from 'dundie.database' (/home/fabio/Documents/cursos/linuxtips/python_base/pb-dundie-rewards/dundie/database.py)</error></testcase></testsuite></testsuites>